Workbook

Sheet README
A1: Hexagro — Shareholder Settlement Data Workbook
A3: How to use
A4: 1. Enter (or paste from Zoho Books' Expense Details export) every transaction in the 'Expenses' sheet — one row per payment. Yellow cells are for input.
A5: 2. Enter sales in the 'Sales' sheet (invoiced and received per unit per month).
A6: 3. Update the 'Banking' sheet snapshot (yellow cells) before each report.
A7: 4. 'Monthly Spend', 'Summary' and 'Settlement' recalculate automatically — verify totals against Zoho Books before sharing.
A8: 5. Cost center names, paid-through names, the raw-material account name, shareholding % and Alam attribution all live in the 'Lists' sheet — edit there and every formula follows.
A10: Legend
A11: Yellow cells = fill in. Grey cells = auto-calculated, do not edit.
A13: Definitions
A14: Cost Center = the unit (Zoho reporting tag): Fibre / Chips / Washing.
A15: Category = 'Expense' (operating costs + fixed assets) or 'Raw Materials' (COGS purchases) — chosen per row via dropdown.
... A22: Append new rows to 'Expenses' and 'Sales' — never overwrite old rows. Update 'Banking'. Share the file (or paste Monthly Spend + Summary + Settlement + Banking) to generate the deck.

Sheet Lists
A1: Cost Centers | B1: Paid Through | C1: Months | D1: Month start | E1: Categories | G1: Shareholding % (edit if ownership changes)
A2: Fibre Unit | B2: Shareholder - Jagadeesan | C2: Apr 2026 | D2: 46113 | E2: Expense | G2: Partner | H2: Fibre Unit | I2: Chips Unit | J2: Washing Unit
A3: Chips Unit | B3: Shareholder - Jagadeshwaran | C3: May 2026 | D3: 46143 | E3: Raw Materials | G3: =B2 -> Shareholder - Jagadeesan | H3: 0.2222 | I3: 0.3333 | J3: 0.3333
A4: Washing Unit | B4: Shareholder - Vellingiri | C4: Jun 2026 | D4: 46174 | E4: Transfer Fund | G4: =B3 -> Shareholder - Jagadeshwaran | H4: 0.2222 | I4: 0.3333 | J4: 0.3333
A5: Alam Cocos | B5: Vikas | C5: Jul 2026 | D5: 46204 | G5: =B4 -> Shareholder - Vellingiri | H5: 0.2222 | I5: 0.3333 | J5: 0.3333
A6: Old Transactions | B6: Payable to Alam | C6: Aug 2026 | D6: 46235 | G6: =B5 -> Vikas | H6: 0.3333 | I6: 0 | J6: 0
B7: Union Bank - CC | C7: Sep 2026 | D7: 46266
B8: Union Bank - Current | C8: Oct 2026 | D8: 46296 | G8: Alam attribution (share of Alam spend counted as each partner's contribution)
B9: Union Bank - Term Loan | C9: Nov 2026 | D9: 46327 | G9: Partner | H9: Alam share
C10: Dec 2026 | D10: 46357 | G10: =B2 -> Shareholder - Jagadeesan | H10: 0.5
C11: Jan 2027 | D11: 46388 | G11: =B3 -> Shareholder - Jagadeshwaran | H11: 0.5
C12: Feb 2027 | D12: 46419 | G12: =B4 -> Shareholder - Vellingiri | H12: 0
C13: Mar 2027 | D13: 46447 | G13: =B5 -> Vikas | H13: 0

Sheet Pivot

Sheet Debit
A1: Date | B1: Cost Center | C1: Type | D1: Account | E1: Paid Through | F1: Description | G1: Total Amount (₹)
A2: 46113 | B2: Chips Unit | C2: Expense | D2: Bank Interest | E2: Payable to Alam | F2: one third of March interest as shared | G2: 29126
A3: 46115 | B3: Washing Unit | C3: Expense | D3: Administration Expense | E3: Shareholder - Jagadeshwaran | F3: documentation | G3: 500
A4: 46118 | B4: Chips Unit | C4: Expense | D4: Building | E4: Payable to Alam | F4: IMPSAR/609612463859/M Arun/xxxxxxxxxxxx8656 Hollow blocks - 300 nos. | G4: 13200
A5: 46119 | B5: Washing Unit | C5: Expense | D5: Land | E5: Payable to Alam | F5: EC and CC online copies | G5: 3427
A6: 46122 | B6: Washing Unit | C6: Expense | D6: Printing and Stationery | E6: Shareholder - Jagadeesan | F6: CC of parent docs + EC prints for legal | G6: 230
A7: 46126 | B7: Chips Unit | C7: Expense | D7: Electricity Bills | E7: Payable to Alam | F7: one third of March eb blil as shared | G7: 7992
A8: 46128 | B8: Chips Unit | C8: Expense | D8: Repairs and Maintenance | E8: Payable to Alam | F8: expenses incurred since the shareholding agreement (refer the xl sheet) | G8: 17000
A9: 46130 | B9: Chips Unit | C9: Expense | D9: Materials | E9: Payable to Alam | F9: 4" cutting wheel - 100 nos. , golden bullet , orient hardwares | G9: 1168
A10: 46130 | B10: Chips Unit | C10: Expense | D10: Materials | E10: Payable to Alam | F10: welding rod - 3 nos. | G10: 991
A11: 46130 | B11: Chips Unit | C11: Expense | D11: Labor | E11: Payable to Alam | F11: from 13- apr till 18-apr: 3240 - welder; 860 - santhosh; 350 - radha | G11: 4450
A12: 46130 | B12: Chips Unit | C12: Expense | D12: Materials | E12: Shareholder - Jagadeesan | F12: 20 nos. of 1" shaft for coco chips | G12: 5414
A13: 46130 | B13: Chips Unit | C13: Expense | D13: Materials | E13: Shareholder - Jagadeshwaran | F13: 20 nos. of 1" shaft for coco chips | G13: 500
... A68: 46182 | B68: Chips Unit | C68: Expense | D68: Materials | E68: Shareholder - Jagadeesan | F68: srs veegrip belt b-76, gpay | G68: 380
A69: 46183 | B69: Chips Unit | C69: Expense | D69: Bank Fees and Charges | E69: Union Bank - CC | G69: 44.88
A70: 46183 | B70: Washing Unit | C70: Expense | D70: Repairs and Maintenance | E70: Payable to Alam | F70: IMPSAR/616123426319/Subramaniam Pal/xxxxxxxxxx2237 Jcb for 10 hrs + batta | G70: 11600
A71: 46183 | B71: Washing Unit | C71: Expense | D71: Administration Expense | E71: Shareholder - Jagadeesan | F71: 2 stamps for hexagro - one for seal and one round seal, gpay | G71: 850
A72: 46184 | B72: Washing Unit | C72: Expense | D72: Administration Expense | E72: Shareholder - Jagadeesan | F72: AIF Application commission, Gpay | G72: 3000
A73: 46185 | B73: Fibre Unit | C73: Expense | D73: Electricity Bills | E73: Payable to Alam | F73: electricity bill | G73: 31566
A74: 46185 | B74: Chips Unit | C74: Expense | D74: Electrical Expenses | E74: Payable to Alam | F74: 20% of the eb bill | G74: 7891
A75: 46186 | B75: Chips Unit | C75: Expense | D75: Employee Salaries | E75: Payable to Alam | F75: weekly salary chips unit - ₹33,869 check attendance sheet | G75: 33869
A76: 46187 | B76: Washing Unit | C76: Expense | D76: Labor | E76: Shareholder - Jagadeesan | F76: To Sudhakar for markings of bunker | G76: 1000
A77: 46188 | B77: Chips Unit | C77: Expense | D77: Construction Expense | E77: Payable to Alam | F77: sakthi mariamman bill #1393 | G77: 9800
A78: 46188 | B78: Washing Unit | C78: Expense | D78: Employee Salaries | E78: Payable to Alam | F78: weekly salary | G78: 590
A79: 46188 | B79: Washing Unit | C79: Expense | D79: Materials | E79: Shareholder - Jagadeesan | F79: For Vellingiri msand/jalli | G79: 20000
A80: 46189 | B80: Chips Unit | C80: Raw Materials | D80: Raw Materials | E80: Union Bank - CC | F80: Vellingiri Senthilkumar | G80: 93753
A81: 46189 | B81: Chips Unit | C81: Raw Materials | D81: Raw Materials | E81: Union Bank - CC | F81: Vellingiri Senthilkumar | G81: 43659
... A111: 46200 | B111: Fibre Unit | C111: Expense | D111: Employee Salaries - Loaders | E111: Shareholder - Jagadeesan | F111: Gpay to Radha for weigh bridge | G111: 300
A112: 46200 | B112: Chips Unit | C112: Expense | D112: Bank Fees and Charges | E112: Union Bank - CC | G112: 67.29
A113: 46200 | B113: Chips Unit | C113: Expense | D113: Bank Fees and Charges | E113: Payable to Alam | G113: 28
A114: 46200 | B114: Fibre Unit | C114: Expense | D114: Employee Salaries | E114: Payable to Alam | F114: weekly salary 120kg labor - ₹4,508 check attendance sheet | G114: 4508
A115: 46200 | B115: Chips Unit | C115: Expense | D115: Employee Salaries | E115: Payable to Alam | F115: weekly salary check attendance sheet , also attached | G115: 47790
A116: 46201 | B116: Washing Unit | C116: Expense | D116: Repairs and Maintenance | E116: Payable to Alam | F116: for subramaniam jcb hexagro2 | G116: 12680
A117: 46202 | B117: Chips Unit | C117: Expense | D117: Bank Fees and Charges | E117: Union Bank - CC | F117: DOC V ETTING CHRGS FOR 501-60435 | G117: 1500
A118: 46202 | B118: Chips Unit | C118: Expense | D118: Electricity Bills | E118: Payable to Alam | F118: electricity bill | G118: 1144
A119: 46202 | B119: Fibre Unit | C119: Raw Materials | D119: Raw Materials | E119: Union Bank - CC | F119: Super Fine Coirs (Fibre) | G119: 109322
A120: 46203 | B120: Washing Unit | C120: Expense | D120: Administration Expense | E120: Shareholder - Jagadeesan | F120: Legal - Online EC Cash to A Sundarraj Pollachi All documents print | G120: 1900
A121: 46203 | B121: Chips Unit | C121: Expense | D121: Bank Interest | E121: Union Bank - CC | F121: xxxxxxxxxxx0435:Int.Coll:01-06-2026 to 30-06-2026 | G121: 1989
A122: 46203 | B122: Washing Unit | C122: Expense | D122: Administration Expense | E122: Payable to Alam | F122: certified copy | G122: 541
A123: 46203 | B123: Chips Unit | C123: Raw Materials | D123: Raw Materials | E123: Union Bank - CC | F123: Periyanaickenpalayam Broker (Green Husk) | G123: 18250
...

Sheet Credit
A1: Date | B1: Cost Center | C1: Type | D1: Received To | E1: Description | F1: Amount
A2: 46205 | B2: Chips Unit | C2: Transfer Fund | D2: Union Bank - Term Loan | E2: Loan Recovery From : xxxxxxxxxxx0435 | F2: 87671
A3: 46226 | B3: Chips Unit | C3: Transfer Fund | D3: Union Bank - Current | E3: TO CA | F3: 200000
A4: 46229 | B4: Chips Unit | C4: Sales | D4: Union Bank - Current | E4: Thara substrates | F4: 50000
A5: 46229 | B5: Chips Unit | C5: Sales | D5: Union Bank - Current | E5: Thara substrates | F5: 50000
A6: 46232 | B6: Chips Unit | C6: Transfer Fund | D6: Union Bank - Term Loan | E6: Loan Recovery From : xxxxxxxxxxx2381 | F6: 174000
A7: 46217 | B7: Fibre Unit | C7: Sales | D7: Payable to Alam | E7: Old forklift return | F7: 200000
A8: 46219 | B8: Chips Unit | C8: Transfer Fund | D8: Payable to Alam | E8: Return of Alam funds | F8: 13012
A9: 46236 | B9: Chips Unit | C9: Transfer Fund | D9: Union Bank - Current | E9: Only to reconcile the bank accounts match | F9: 730
A10: 46239 | B10: Chips Unit | C10: Transfer Fund | D10: Union Bank - Term Loan | E10: Loan Account Payments For : xxxxxxxxxxx0045 | F10: 90632
A11: 46240 | B11: Chips Unit | C11: Transfer Fund | D11: Union Bank - Current | E11: internal transfer actual is 3,39,475 but the 39,475 belongs to pugazh cocos who also has acct in union bank | F11: 300000
A12: 46245 | B12: Fibre Unit | C12: Sales | D12: Payable to Alam | E12: Old forklift return | F12: 100000
A13: 46246 | B13: Fibre Unit | C13: Sales | D13: Payable to Alam | E13: Old forklift return | F13: 100000

Sheet Fibre_Historical_Exp_by_Alam
A1: Date | B1: Cost Center | C1: Type | D1: Account | E1: Description | F1: Total Amount (₹)
A2: 46116 | B2: Fibre Unit | C2: Expense | D2: Employee Salaries | E2: weekly labor wages | F2: 7359
A3: 46125 | B3: Fibre Unit | C3: Expense | D3: Construction Expense | E3: JCB and tractor - subramaniam | F3: 8400
A4: 46126 | B4: Fibre Unit | C4: Expense | D4: Vehicles | E4: Forklift oil | F4: 3700
A5: 46126 | B5: Fibre Unit | C5: Expense | D5: Vehicles | E5: hose purchase amount & petrol | F5: 450
A6: 46130 | B6: Fibre Unit | C6: Expense | D6: Employee Salaries | E6: weekly labor wages | F6: 14604
A7: 46133 | B7: Fibre Unit | C7: Expense | D7: Electrical Expenses | E7: Naveen electricals | F7: 935
A8: 46134 | B8: Fibre Unit | C8: Expense | D8: Repairs and Maintenance | E8: crane for foklift - nanbargal | F8: 3500
A9: 46136 | B9: Fibre Unit | C9: Expense | D9: Repairs and Maintenance | E9: patta drill & cutting - chellam agencies | F9: 11500
A10: 46136 | B10: Fibre Unit | C10: Expense | D10: Repairs and Maintenance | E10: Alam Labor & Expenses Book | F10: 6350
A11: 46137 | B11: Fibre Unit | C11: Expense | D11: Fuel Expense | E11: bowser diesel | F11: 15308
A12: 46143 | B12: Fibre Unit | C12: Expense | D12: Administration Expense | E12: Jio recharge | F12: 100
A13: 46144 | B13: Fibre Unit | C13: Expense | D13: Employee Salaries | E13: weekly labor wages | F13: 1666
... A31: 46194 | B31: Fibre Unit | C31: Expense | D31: Employee Salaries - Loaders | E31: radha loading, weigh bridge | F31: 2799
E32: Total | F32: =SUM(F2:F31) -> 357464
A33: note: these expenses are already reconciled with Vikas in the planning sheet | E33: Alam contribution (66.666%) | F33: =F32*66.667% -> 238310.52

Sheet Sales
A1: Month | B1: Cost Center | C1: Invoiced (₹) | D1: Received (₹) | E1: Notes
A2: Apr 2026 | B2: Chips Unit | C2: 294840 | D2: 100000 | E2: thara substrates
A3: Jul 2026 | B3: Fibre Unit | C3: 739000 | D3: 0 | E3: alaya coirs 3 containers

Sheet Outstanding
A1: Outstanding payments (unpaid — informational, not part of spend or settlement)
A3: Item / Party | B3: Cost Center | C3: Amount (₹) | D3: Notes
A4: Sakthi Mariamman | B4: Washing Unit | C4: 484690
A5: HP Cocos | B5: Fibre Unit | C5: 346000
A6: Rhythm Fibres | B6: Fibre Unit | D6: 13 fibre loads, ₹ to be calc.
A7: Vellingiri Field Work | B7: Washing Unit | C7: -7464 | D7: alam labor work
A8: Naveen Periyakalanthai | B8: Fibre Unit | C8: 56160
A9: Alam Cocos | B9: Fibre Unit | D9: Yet to be calculated
A10: Naveen Electricals | B10: Chips Unit | C10: 0
A11: Rithvik Pipe Company | B11: Washing Unit | C11: 151199 | D11: bill 2454
A14: Total | C14: =SUM(C4:C13) -> 1030585

Sheet Banking
A1: Banking snapshot (update before each report)
A3: As-of date | B3: 46257
A4: CC limit (₹) | B4: 5000000
A5: CC utilised (₹) | B5: 3718510
A6: CC available (₹) | B6: =B4-B5 -> 1281490
A7: Current account balance (₹) | B7: 228763
A8: Term Loan outstanding (₹) | B8: 13326000
A9: Payable to Alam — opening (₹) | B9: 0
A10: Alam inflows this FY (₹) | B10: 0
A11: Alam funds utilised this FY (₹) | B11: =SUMIFS(Debit!$G:$G,Debit!$E:$E,Lists!$B$6) -> 1488558.2
A12: Payable to Alam — closing (₹) | B12: =B9+B10-B11 -> -1488558.2
A14: 'Alam funds utilised' is auto-summed from Expenses rows where Paid Through = Alam.

Sheet Monthly Spend
A1: Monthly spend by cost center and paid-through — auto-calculated from Expenses (do not edit)
A3: Month | B3: Cost Center | C3: Paid Through | D3: Expenses (₹) | E3: Raw Materials (₹) | F3: Total (₹)
A4: Apr 2026 | B4: =Lists!$A$2 -> Fibre Unit | C4: =Lists!$B$2 -> Shareholder - Jagadeesan | D4: =SUMIFS(Debit!$G:$G,Debit!$B:$B,Lists!$A$2,Debit!$E:$E,Lists!$B$2,Debit!$C:$C,Lists!$E$2,Debit!$A:$A,">="&Lists!$D$2,Debit!$A:$A,"<"&EDATE(Lists!$D$2,1)) -> 0 | E4: =SUMIFS(Debit!$G:$G,Debit!$B:$B,Lists!$A$2,Debit!$E:$E,Lists!$B$2,Debit!$C:$C,Lists!$E$3,Debit!$A:$A,">="&Lists!$D$2,Debit!$A:$A,"<"&EDATE(Lists!$D$2,1)) -> 0 | F4: =D4+E4 -> 0
A5: Apr 2026 | B5: =Lists!$A$2 -> Fibre Unit | C5: =Lists!$B$3 -> Shareholder - Jagadeshwaran | D5: =SUMIFS(Debit!$G:$G,Debit!$B:$B,Lists!$A$2,Debit!$E:$E,Lists!$B$3,Debit!$C:$C,Lists!$E$2,Debit!$A:$A,">="&Lists!$D$2,Debit!$A:$A,"<"&EDATE(Lists!$D$2,1)) -> 0 | E5: =SUMIFS(Debit!$G:$G,Debit!$B:$B,Lists!$A$2,Debit!$E:$E,Lists!$B$3,Debit!$C:$C,Lists!$E$3,Debit!$A:$A,">="&Lists!$D$2,Debit!$A:$A,"<"&EDATE(Lists!$D$2,1)) -> 0 | F5: =D5+E5 -> 0
A6: Apr 2026 | B6: =Lists!$A$2 -> Fibre Unit | C6: =Lists!$B$4 -> Shareholder - Vellingiri | D6: =SUMIFS(Debit!$G:$G,Debit!$B:$B,Lists!$A$2,Debit!$E:$E,Lists!$B$4,Debit!$C:$C,Lists!$E$2,Debit!$A:$A,">="&Lists!$D$2,Debit!$A:$A,"<"&EDATE(Lists!$D$2,1)) -> 0 | E6: =SUMIFS(Debit!$G:$G,Debit!$B:$B,Lists!$A$2,Debit!$E:$E,Lists!$B$4,Debit!$C:$C,Lists!$E$3,Debit!$A:$A,">="&Lists!$D$2,Debit!$A:$A,"<"&EDATE(Lists!$D$2,1)) -> 0 | F6: =D6+E6 -> 0
A7: Apr 2026 | B7: =Lists!$A$2 -> Fibre Unit | C7: =Lists!$B$5 -> Vikas | D7: =SUMIFS(Debit!$G:$G,Debit!$B:$B,Lists!$A$2,Debit!$E:$E,Lists!$B$5,Debit!$C:$C,Lists!$E$2,Debit!$A:$A,">="&Lists!$D$2,Debit!$A:$A,"<"&EDATE(Lists!$D$2,1)) -> 0 | E7: =SUMIFS(Debit!$G:$G,Debit!$B:$B,Lists!$A$2,Debit!$E:$E,Lists!$B$5,Debit!$C:$C,Lists!$E$3,Debit!$A:$A,">="&Lists!$D$2,Debit!$A:$A,"<"&EDATE(Lists!$D$2,1)) -> 0 | F7: =D7+E7 -> 0
A8: Apr 2026 | B8: =Lists!$A$2 -> Fibre Unit | C8: =Lists!$B$6 -> Payable to Alam | D8: =SUMIFS(Debit!$G:$G,Debit!$B:$B,Lists!$A$2,Debit!$E:$E,Lists!$B$6,Debit!$C:$C,Lists!$E$2,Debit!$A:$A,">="&Lists!$D$2,Debit!$A:$A,"<"&EDATE(Lists!$D$2,1)) -> 0 | E8: =SUMIFS(Debit!$G:$G,Debit!$B:$B,Lists!$A$2,Debit!$E:$E,Lists!$B$6,Debit!$C:$C,Lists!$E$3,Debit!$A:$A,">="&Lists!$D$2,Debit!$A:$A,"<"&EDATE(Lists!$D$2,1)) -> 0 | F8: =D8+E8 -> 0
A9: Apr 2026 | B9: =Lists!$A$2 -> Fibre Unit | C9: =Lists!$B$7 -> Union Bank - CC | D9: =SUMIFS(Debit!$G:$G,Debit!$B:$B,Lists!$A$2,Debit!$E:$E,Lists!$B$7,Debit!$C:$C,Lists!$E$2,Debit!$A:$A,">="&Lists!$D$2,Debit!$A:$A,"<"&EDATE(Lists!$D$2,1)) -> 0 | E9: =SUMIFS(Debit!$G:$G,Debit!$B:$B,Lists!$A$2,Debit!$E:$E,Lists!$B$7,Debit!$C:$C,Lists!$E$3,Debit!$A:$A,">="&Lists!$D$2,Debit!$A:$A,"<"&EDATE(Lists!$D$2,1)) -> 0 | F9: =D9+E9 -> 0
A10: Apr 2026 | B10: =Lists!$A$2 -> Fibre Unit | C10: =Lists!$B$8 -> Union Bank - Current | D10: =SUMIFS(Debit!$G:$G,Debit!$B:$B,Lists!$A$2,Debit!$E:$E,Lists!$B$8,Debit!$C:$C,Lists!$E$2,Debit!$A:$A,">="&Lists!$D$2,Debit!$A:$A,"<"&EDATE(Lists!$D$2,1)) -> 0 | E10: =SUMIFS(Debit!$G:$G,Debit!$B:$B,Lists!$A$2,Debit!$E:$E,Lists!$B$8,Debit!$C:$C,Lists!$E$3,Debit!$A:$A,">="&Lists!$D$2,Debit!$A:$A,"<"&EDATE(Lists!$D$2,1)) -> 0 | F10: =D10+E10 -> 0
A11: Apr 2026 | B11: =Lists!$A$3 -> Chips Unit | C11: =Lists!$B$2 -> Shareholder - Jagadeesan | D11: =SUMIFS(Debit!$G:$G,Debit!$B:$B,Lists!$A$3,Debit!$E:$E,Lists!$B$2,Debit!$C:$C,Lists!$E$2,Debit!$A:$A,">="&Lists!$D$2,Debit!$A:$A,"<"&EDATE(Lists!$D$2,1)) -> 23020 | E11: =SUMIFS(Debit!$G:$G,Debit!$B:$B,Lists!$A$3,Debit!$E:$E,Lists!$B$2,Debit!$C:$C,Lists!$E$3,Debit!$A:$A,">="&Lists!$D$2,Debit!$A:$A,"<"&EDATE(Lists!$D$2,1)) -> 0 | F11: =D11+E11 -> 23020
A12: Apr 2026 | B12: =Lists!$A$3 -> Chips Unit | C12: =Lists!$B$3 -> Shareholder - Jagadeshwaran | D12: =SUMIFS(Debit!$G:$G,Debit!$B:$B,Lists!$A$3,Debit!$E:$E,Lists!$B$3,Debit!$C:$C,Lists!$E$2,Debit!$A:$A,">="&Lists!$D$2,Debit!$A:$A,"<"&EDATE(Lists!$D$2,1)) -> 500 | E12: =SUMIFS(Debit!$G:$G,Debit!$B:$B,Lists!$A$3,Debit!$E:$E,Lists!$B$3,Debit!$C:$C,Lists!$E$3,Debit!$A:$A,">="&Lists!$D$2,Debit!$A:$A,"<"&EDATE(Lists!$D$2,1)) -> 0 | F12: =D12+E12 -> 500
A13: Apr 2026 | B13: =Lists!$A$3 -> Chips Unit | C13: =Lists!$B$4 -> Shareholder - Vellingiri | D13: =SUMIFS(Debit!$G:$G,Debit!$B:$B,Lists!$A$3,Debit!$E:$E,Lists!$B$4,Debit!$C:$C,Lists!$E$2,Debit!$A:$A,">="&Lists!$D$2,Debit!$A:$A,"<"&EDATE(Lists!$D$2,1)) -> 0 | E13: =SUMIFS(Debit!$G:$G,Debit!$B:$B,Lists!$A$3,Debit!$E:$E,Lists!$B$4,Debit!$C:$C,Lists!$E$3,Debit!$A:$A,">="&Lists!$D$2,Debit!$A:$A,"<"&EDATE(Lists!$D$2,1)) -> 0 | F13: =D13+E13 -> 0
A14: Apr 2026 | B14: =Lists!$A$3 -> Chips Unit | C14: =Lists!$B$5 -> Vikas | D14: =SUMIFS(Debit!$G:$G,Debit!$B:$B,Lists!$A$3,Debit!$E:$E,Lists!$B$5,Debit!$C:$C,Lists!$E$2,Debit!$A:$A,">="&Lists!$D$2,Debit!$A:$A,"<"&EDATE(Lists!$D$2,1)) -> 0 | E14: =SUMIFS(Debit!$G:$G,Debit!$B:$B,Lists!$A$3,Debit!$E:$E,Lists!$B$5,Debit!$C:$C,Lists!$E$3,Debit!$A:$A,">="&Lists!$D$2,Debit!$A:$A,"<"&EDATE(Lists!$D$2,1)) -> 0 | F14: =D14+E14 -> 0
A15: Apr 2026 | B15: =Lists!$A$3 -> Chips Unit | C15: =Lists!$B$6 -> Payable to Alam | D15: =SUMIFS(Debit!$G:$G,Debit!$B:$B,Lists!$A$3,Debit!$E:$E,Lists!$B$6,Debit!$C:$C,Lists!$E$2,Debit!$A:$A,">="&Lists!$D$2,Debit!$A:$A,"<"&EDATE(Lists!$D$2,1)) -> 178569 | E15: =SUMIFS(Debit!$G:$G,Debit!$B:$B,Lists!$A$3,Debit!$E:$E,Lists!$B$6,Debit!$C:$C,Lists!$E$3,Debit!$A:$A,">="&Lists!$D$2,Debit!$A:$A,"<"&EDATE(Lists!$D$2,1)) -> 0 | F15: =D15+E15 -> 178569
A16: Apr 2026 | B16: =Lists!$A$3 -> Chips Unit | C16: =Lists!$B$7 -> Union Bank - CC | D16: =SUMIFS(Debit!$G:$G,Debit!$B:$B,Lists!$A$3,Debit!$E:$E,Lists!$B$7,Debit!$C:$C,Lists!$E$2,Debit!$A:$A,">="&Lists!$D$2,Debit!$A:$A,"<"&EDATE(Lists!$D$2,1)) -> 0 | E16: =SUMIFS(Debit!$G:$G,Debit!$B:$B,Lists!$A$3,Debit!$E:$E,Lists!$B$7,Debit!$C:$C,Lists!$E$3,Debit!$A:$A,">="&Lists!$D$2,Debit!$A:$A,"<"&EDATE(Lists!$D$2,1)) -> 0 | F16: =D16+E16 -> 0
A17: Apr 2026 | B17: =Lists!$A$3 -> Chips Unit | C17: =Lists!$B$8 -> Union Bank - Current | D17: =SUMIFS(Debit!$G:$G,Debit!$B:$B,Lists!$A$3,Debit!$E:$E,Lists!$B$8,Debit!$C:$C,Lists!$E$2,Debit!$A:$A,">="&Lists!$D$2,Debit!$A:$A,"<"&EDATE(Lists!$D$2,1)) -> 0 | E17: =SUMIFS(Debit!$G:$G,Debit!$B:$B,Lists!$A$3,Debit!$E:$E,Lists!$B$8,Debit!$C:$C,Lists!$E$3,Debit!$A:$A,">="&Lists!$D$2,Debit!$A:$A,"<"&EDATE(Lists!$D$2,1)) -> 0 | F17: =D17+E17 -> 0
A18: Apr 2026 | B18: =Lists!$A$4 -> Washing Unit | C18: =Lists!$B$2 -> Shareholder - Jagadeesan | D18: =SUMIFS(Debit!$G:$G,Debit!$B:$B,Lists!$A$4,Debit!$E:$E,Lists!$B$2,Debit!$C:$C,Lists!$E$2,Debit!$A:$A,">="&Lists!$D$2,Debit!$A:$A,"<"&EDATE(Lists!$D$2,1)) -> 4330 | E18: =SUMIFS(Debit!$G:$G,Debit!$B:$B,Lists!$A$4,Debit!$E:$E,Lists!$B$2,Debit!$C:$C,Lists!$E$3,Debit!$A:$A,">="&Lists!$D$2,Debit!$A:$A,"<"&EDATE(Lists!$D$2,1)) -> 0 | F18: =D18+E18 -> 4330
A19: Apr 2026 | B19: =Lists!$A$4 -> Washing Unit | C19: =Lists!$B$3 -> Shareholder - Jagadeshwaran | D19: =SUMIFS(Debit!$G:$G,Debit!$B:$B,Lists!$A$4,Debit!$E:$E,Lists!$B$3,Debit!$C:$C,Lists!$E$2,Debit!$A:$A,">="&Lists!$D$2,Debit!$A:$A,"<"&EDATE(Lists!$D$2,1)) -> 500 | E19: =SUMIFS(Debit!$G:$G,Debit!$B:$B,Lists!$A$4,Debit!$E:$E,Lists!$B$3,Debit!$C:$C,Lists!$E$3,Debit!$A:$A,">="&Lists!$D$2,Debit!$A:$A,"<"&EDATE(Lists!$D$2,1)) -> 0 | F19: =D19+E19 -> 500
A20: Apr 2026 | B20: =Lists!$A$4 -> Washing Unit | C20: =Lists!$B$4 -> Shareholder - Vellingiri | D20: =SUMIFS(Debit!$G:$G,Debit!$B:$B,Lists!$A$4,Debit!$E:$E,Lists!$B$4,Debit!$C:$C,Lists!$E$2,Debit!$A:$A,">="&Lists!$D$2,Debit!$A:$A,"<"&EDATE(Lists!$D$2,1)) -> 0 | E20: =SUMIFS(Debit!$G:$G,Debit!$B:$B,Lists!$A$4,Debit!$E:$E,Lists!$B$4,Debit!$C:$C,Lists!$E$3,Debit!$A:$A,">="&Lists!$D$2,Debit!$A:$A,"<"&EDATE(Lists!$D$2,1)) -> 0 | F20: =D20+E20 -> 0
A21: Apr 2026 | B21: =Lists!$A$4 -> Washing Unit | C21: =Lists!$B$5 -> Vikas | D21: =SUMIFS(Debit!$G:$G,Debit!$B:$B,Lists!$A$4,Debit!$E:$E,Lists!$B$5,Debit!$C:$C,Lists!$E$2,Debit!$A:$A,">="&Lists!$D$2,Debit!$A:$A,"<"&EDATE(Lists!$D$2,1)) -> 0 | E21: =SUMIFS(Debit!$G:$G,Debit!$B:$B,Lists!$A$4,Debit!$E:$E,Lists!$B$5,Debit!$C:$C,Lists!$E$3,Debit!$A:$A,">="&Lists!$D$2,Debit!$A:$A,"<"&EDATE(Lists!$D$2,1)) -> 0 | F21: =D21+E21 -> 0
A22: Apr 2026 | B22: =Lists!$A$4 -> Washing Unit | C22: =Lists!$B$6 -> Payable to Alam | D22: =SUMIFS(Debit!$G:$G,Debit!$B:$B,Lists!$A$4,Debit!$E:$E,Lists!$B$6,Debit!$C:$C,Lists!$E$2,Debit!$A:$A,">="&Lists!$D$2,Debit!$A:$A,"<"&EDATE(Lists!$D$2,1)) -> 3427 | E22: =SUMIFS(Debit!$G:$G,Debit!$B:$B,Lists!$A$4,Debit!$E:$E,Lists!$B$6,Debit!$C:$C,Lists!$E$3,Debit!$A:$A,">="&Lists!$D$2,Debit!$A:$A,"<"&EDATE(Lists!$D$2,1)) -> 0 | F22: =D22+E22 -> 3427
A23: Apr 2026 | B23: =Lists!$A$4 -> Washing Unit | C23: =Lists!$B$7 -> Union Bank - CC | D23: =SUMIFS(Debit!$G:$G,Debit!$B:$B,Lists!$A$4,Debit!$E:$E,Lists!$B$7,Debit!$C:$C,Lists!$E$2,Debit!$A:$A,">="&Lists!$D$2,Debit!$A:$A,"<"&EDATE(Lists!$D$2,1)) -> 0 | E23: =SUMIFS(Debit!$G:$G,Debit!$B:$B,Lists!$A$4,Debit!$E:$E,Lists!$B$7,Debit!$C:$C,Lists!$E$3,Debit!$A:$A,">="&Lists!$D$2,Debit!$A:$A,"<"&EDATE(Lists!$D$2,1)) -> 0 | F23: =D23+E23 -> 0
A24: Apr 2026 | B24: =Lists!$A$4 -> Washing Unit | C24: =Lists!$B$8 -> Union Bank - Current | D24: =SUMIFS(Debit!$G:$G,Debit!$B:$B,Lists!$A$4,Debit!$E:$E,Lists!$B$8,Debit!$C:$C,Lists!$E$2,Debit!$A:$A,">="&Lists!$D$2,Debit!$A:$A,"<"&EDATE(Lists!$D$2,1)) -> 0 | E24: =SUMIFS(Debit!$G:$G,Debit!$B:$B,Lists!$A$4,Debit!$E:$E,Lists!$B$8,Debit!$C:$C,Lists!$E$3,Debit!$A:$A,">="&Lists!$D$2,Debit!$A:$A,"<"&EDATE(Lists!$D$2,1)) -> 0 | F24: =D24+E24 -> 0
A25: May 2026 | B25: =Lists!$A$2 -> Fibre Unit | C25: =Lists!$B$2 -> Shareholder - Jagadeesan | D25: =SUMIFS(Debit!$G:$G,Debit!$B:$B,Lists!$A$2,Debit!$E:$E,Lists!$B$2,Debit!$C:$C,Lists!$E$2,Debit!$A:$A,">="&Lists!$D$3,Debit!$A:$A,"<"&EDATE(Lists!$D$3,1)) -> 0 | E25: =SUMIFS(Debit!$G:$G,Debit!$B:$B,Lists!$A$2,Debit!$E:$E,Lists!$B$2,Debit!$C:$C,Lists!$E$3,Debit!$A:$A,">="&Lists!$D$3,Debit!$A:$A,"<"&EDATE(Lists!$D$3,1)) -> 0 | F25: =D25+E25 -> 0
A26: May 2026 | B26: =Lists!$A$2 -> Fibre Unit | C26: =Lists!$B$3 -> Shareholder - Jagadeshwaran | D26: =SUMIFS(Debit!$G:$G,Debit!$B:$B,Lists!$A$2,Debit!$E:$E,Lists!$B$3,Debit!$C:$C,Lists!$E$2,Debit!$A:$A,">="&Lists!$D$3,Debit!$A:$A,"<"&EDATE(Lists!$D$3,1)) -> 0 | E26: =SUMIFS(Debit!$G:$G,Debit!$B:$B,Lists!$A$2,Debit!$E:$E,Lists!$B$3,Debit!$C:$C,Lists!$E$3,Debit!$A:$A,">="&Lists!$D$3,Debit!$A:$A,"<"&EDATE(Lists!$D$3,1)) -> 0 | F26: =D26+E26 -> 0
A27: May 2026 | B27: =Lists!$A$2 -> Fibre Unit | C27: =Lists!$B$4 -> Shareholder - Vellingiri | D27: =SUMIFS(Debit!$G:$G,Debit!$B:$B,Lists!$A$2,Debit!$E:$E,Lists!$B$4,Debit!$C:$C,Lists!$E$2,Debit!$A:$A,">="&Lists!$D$3,Debit!$A:$A,"<"&EDATE(Lists!$D$3,1)) -> 0 | E27: =SUMIFS(Debit!$G:$G,Debit!$B:$B,Lists!$A$2,Debit!$E:$E,Lists!$B$4,Debit!$C:$C,Lists!$E$3,Debit!$A:$A,">="&Lists!$D$3,Debit!$A:$A,"<"&EDATE(Lists!$D$3,1)) -> 0 | F27: =D27+E27 -> 0
A28: May 2026 | B28: =Lists!$A$2 -> Fibre Unit | C28: =Lists!$B$5 -> Vikas | D28: =SUMIFS(Debit!$G:$G,Debit!$B:$B,Lists!$A$2,Debit!$E:$E,Lists!$B$5,Debit!$C:$C,Lists!$E$2,Debit!$A:$A,">="&Lists!$D$3,Debit!$A:$A,"<"&EDATE(Lists!$D$3,1)) -> 0 | E28: =SUMIFS(Debit!$G:$G,Debit!$B:$B,Lists!$A$2,Debit!$E:$E,Lists!$B$5,Debit!$C:$C,Lists!$E$3,Debit!$A:$A,">="&Lists!$D$3,Debit!$A:$A,"<"&EDATE(Lists!$D$3,1)) -> 0 | F28: =D28+E28 -> 0
A29: May 2026 | B29: =Lists!$A$2 -> Fibre Unit | C29: =Lists!$B$6 -> Payable to Alam | D29: =SUMIFS(Debit!$G:$G,Debit!$B:$B,Lists!$A$2,Debit!$E:$E,Lists!$B$6,Debit!$C:$C,Lists!$E$2,Debit!$A:$A,">="&Lists!$D$3,Debit!$A:$A,"<"&EDATE(Lists!$D$3,1)) -> 0 | E29: =SUMIFS(Debit!$G:$G,Debit!$B:$B,Lists!$A$2,Debit!$E:$E,Lists!$B$6,Debit!$C:$C,Lists!$E$3,Debit!$A:$A,">="&Lists!$D$3,Debit!$A:$A,"<"&EDATE(Lists!$D$3,1)) -> 0 | F29: =D29+E29 -> 0
A30: May 2026 | B30: =Lists!$A$2 -> Fibre Unit | C30: =Lists!$B$7 -> Union Bank - CC | D30: =SUMIFS(Debit!$G:$G,Debit!$B:$B,Lists!$A$2,Debit!$E:$E,Lists!$B$7,Debit!$C:$C,Lists!$E$2,Debit!$A:$A,">="&Lists!$D$3,Debit!$A:$A,"<"&EDATE(Lists!$D$3,1)) -> 0 | E30: =SUMIFS(Debit!$G:$G,Debit!$B:$B,Lists!$A$2,Debit!$E:$E,Lists!$B$7,Debit!$C:$C,Lists!$E$3,Debit!$A:$A,">="&Lists!$D$3,Debit!$A:$A,"<"&EDATE(Lists!$D$3,1)) -> 0 | F30: =D30+E30 -> 0
A31: May 2026 | B31: =Lists!$A$2 -> Fibre Unit | C31: =Lists!$B$8 -> Union Bank - Current | D31: =SUMIFS(Debit!$G:$G,Debit!$B:$B,Lists!$A$2,Debit!$E:$E,Lists!$B$8,Debit!$C:$C,Lists!$E$2,Debit!$A:$A,">="&Lists!$D$3,Debit!$A:$A,"<"&EDATE(Lists!$D$3,1)) -> 0 | E31: =SUMIFS(Debit!$G:$G,Debit!$B:$B,Lists!$A$2,Debit!$E:$E,Lists!$B$8,Debit!$C:$C,Lists!$E$3,Debit!$A:$A,">="&Lists!$D$3,Debit!$A:$A,"<"&EDATE(Lists!$D$3,1)) -> 0 | F31: =D31+E31 -> 0
A32: May 2026 | B32: =Lists!$A$3 -> Chips Unit | C32: =Lists!$B$2 -> Shareholder - Jagadeesan | D32: =SUMIFS(Debit!$G:$G,Debit!$B:$B,Lists!$A$3,Debit!$E:$E,Lists!$B$2,Debit!$C:$C,Lists!$E$2,Debit!$A:$A,">="&Lists!$D$3,Debit!$A:$A,"<"&EDATE(Lists!$D$3,1)) -> 48604 | E32: =SUMIFS(Debit!$G:$G,Debit!$B:$B,Lists!$A$3,Debit!$E:$E,Lists!$B$2,Debit!$C:$C,Lists!$E$3,Debit!$A:$A,">="&Lists!$D$3,Debit!$A:$A,"<"&EDATE(Lists!$D$3,1)) -> 0 | F32: =D32+E32 -> 48604
A33: May 2026 | B33: =Lists!$A$3 -> Chips Unit | C33: =Lists!$B$3 -> Shareholder - Jagadeshwaran | D33: =SUMIFS(Debit!$G:$G,Debit!$B:$B,Lists!$A$3,Debit!$E:$E,Lists!$B$3,Debit!$C:$C,Lists!$E$2,Debit!$A:$A,">="&Lists!$D$3,Debit!$A:$A,"<"&EDATE(Lists!$D$3,1)) -> 265431 | E33: =SUMIFS(Debit!$G:$G,Debit!$B:$B,Lists!$A$3,Debit!$E:$E,Lists!$B$3,Debit!$C:$C,Lists!$E$3,Debit!$A:$A,">="&Lists!$D$3,Debit!$A:$A,"<"&EDATE(Lists!$D$3,1)) -> 0 | F33: =D33+E33 -> 265431
A34: May 2026 | B34: =Lists!$A$3 -> Chips Unit | C34: =Lists!$B$4 -> Shareholder - Vellingiri | D34: =SUMIFS(Debit!$G:$G,Debit!$B:$B,Lists!$A$3,Debit!$E:$E,Lists!$B$4,Debit!$C:$C,Lists!$E$2,Debit!$A:$A,">="&Lists!$D$3,Debit!$A:$A,"<"&EDATE(Lists!$D$3,1)) -> 0 | E34: =SUMIFS(Debit!$G:$G,Debit!$B:$B,Lists!$A$3,Debit!$E:$E,Lists!$B$4,Debit!$C:$C,Lists!$E$3,Debit!$A:$A,">="&Lists!$D$3,Debit!$A:$A,"<"&EDATE(Lists!$D$3,1)) -> 0 | F34: =D34+E34 -> 0
A35: May 2026 | B35: =Lists!$A$3 -> Chips Unit | C35: =Lists!$B$5 -> Vikas | D35: =SUMIFS(Debit!$G:$G,Debit!$B:$B,Lists!$A$3,Debit!$E:$E,Lists!$B$5,Debit!$C:$C,Lists!$E$2,Debit!$A:$A,">="&Lists!$D$3,Debit!$A:$A,"<"&EDATE(Lists!$D$3,1)) -> 0 | E35: =SUMIFS(Debit!$G:$G,Debit!$B:$B,Lists!$A$3,Debit!$E:$E,Lists!$B$5,Debit!$C:$C,Lists!$E$3,Debit!$A:$A,">="&Lists!$D$3,Debit!$A:$A,"<"&EDATE(Lists!$D$3,1)) -> 0 | F35: =D35+E35 -> 0
A36: May 2026 | B36: =Lists!$A$3 -> Chips Unit | C36: =Lists!$B$6 -> Payable to Alam | D36: =SUMIFS(Debit!$G:$G,Debit!$B:$B,Lists!$A$3,Debit!$E:$E,Lists!$B$6,Debit!$C:$C,Lists!$E$2,Debit!$A:$A,">="&Lists!$D$3,Debit!$A:$A,"<"&EDATE(Lists!$D$3,1)) -> 218070.41 | E36: =SUMIFS(Debit!$G:$G,Debit!$B:$B,Lists!$A$3,Debit!$E:$E,Lists!$B$6,Debit!$C:$C,Lists!$E$3,Debit!$A:$A,">="&Lists!$D$3,Debit!$A:$A,"<"&EDATE(Lists!$D$3,1)) -> 0 | F36: =D36+E36 -> 218070.41
A37: May 2026 | B37: =Lists!$A$3 -> Chips Unit | C37: =Lists!$B$7 -> Union Bank - CC | D37: =SUMIFS(Debit!$G:$G,Debit!$B:$B,Lists!$A$3,Debit!$E:$E,Lists!$B$7,Debit!$C:$C,Lists!$E$2,Debit!$A:$A,">="&Lists!$D$3,Debit!$A:$A,"<"&EDATE(Lists!$D$3,1)) -> 20194.16 | E37: =SUMIFS(Debit!$G:$G,Debit!$B:$B,Lists!$A$3,Debit!$E:$E,Lists!$B$7,Debit!$C:$C,Lists!$E$3,Debit!$A:$A,">="&Lists!$D$3,Debit!$A:$A,"<"&EDATE(Lists!$D$3,1)) -> 0 | F37: =D37+E37 -> 20194.16
A38: May 2026 | B38: =Lists!$A$3 -> Chips Unit | C38: =Lists!$B$8 -> Union Bank - Current | D38: =SUMIFS(Debit!$G:$G,Debit!$B:$B,Lists!$A$3,Debit!$E:$E,Lists!$B$8,Debit!$C:$C,Lists!$E$2,Debit!$A:$A,">="&Lists!$D$3,Debit!$A:$A,"<"&EDATE(Lists!$D$3,1)) -> 0 | E38: =SUMIFS(Debit!$G:$G,Debit!$B:$B,Lists!$A$3,Debit!$E:$E,Lists!$B$8,Debit!$C:$C,Lists!$E$3,Debit!$A:$A,">="&Lists!$D$3,Debit!$A:$A,"<"&EDATE(Lists!$D$3,1)) -> 0 | F38: =D38+E38 -> 0
A39: May 2026 | B39: =Lists!$A$4 -> Washing Unit | C39: =Lists!$B$2 -> Shareholder - Jagadeesan | D39: =SUMIFS(Debit!$G:$G,Debit!$B:$B,Lists!$A$4,Debit!$E:$E,Lists!$B$2,Debit!$C:$C,Lists!$E$2,Debit!$A:$A,">="&Lists!$D$3,Debit!$A:$A,"<"&EDATE(Lists!$D$3,1)) -> 12094 | E39: =SUMIFS(Debit!$G:$G,Debit!$B:$B,Lists!$A$4,Debit!$E:$E,Lists!$B$2,Debit!$C:$C,Lists!$E$3,Debit!$A:$A,">="&Lists!$D$3,Debit!$A:$A,"<"&EDATE(Lists!$D$3,1)) -> 0 | F39: =D39+E39 -> 12094
A40: May 2026 | B40: =Lists!$A$4 -> Washing Unit | C40: =Lists!$B$3 -> Shareholder - Jagadeshwaran | D40: =SUMIFS(Debit!$G:$G,Debit!$B:$B,Lists!$A$4,Debit!$E:$E,Lists!$B$3,Debit!$C:$C,Lists!$E$2,Debit!$A:$A,">="&Lists!$D$3,Debit!$A:$A,"<"&EDATE(Lists!$D$3,1)) -> 0 | E40: =SUMIFS(Debit!$G:$G,Debit!$B:$B,Lists!$A$4,Debit!$E:$E,Lists!$B$3,Debit!$C:$C,Lists!$E$3,Debit!$A:$A,">="&Lists!$D$3,Debit!$A:$A,"<"&EDATE(Lists!$D$3,1)) -> 0 | F40: =D40+E40 -> 0
A41: May 2026 | B41: =Lists!$A$4 -> Washing Unit | C41: =Lists!$B$4 -> Shareholder - Vellingiri | D41: =SUMIFS(Debit!$G:$G,Debit!$B:$B,Lists!$A$4,Debit!$E:$E,Lists!$B$4,Debit!$C:$C,Lists!$E$2,Debit!$A:$A,">="&Lists!$D$3,Debit!$A:$A,"<"&EDATE(Lists!$D$3,1)) -> 0 | E41: =SUMIFS(Debit!$G:$G,Debit!$B:$B,Lists!$A$4,Debit!$E:$E,Lists!$B$4,Debit!$C:$C,Lists!$E$3,Debit!$A:$A,">="&Lists!$D$3,Debit!$A:$A,"<"&EDATE(Lists!$D$3,1)) -> 0 | F41: =D41+E41 -> 0
...

Sheet Summary
A1: FY-to-date summary — auto-calculated from Expenses (do not edit)
A3: =Lists!$A$2 -> Fibre Unit
A4: Paid Through | B4: Expenses | C4: Raw Materials | D4: Other Debits | E4: Credit | F4: Total
A5: =Lists!$B$2 -> Shareholder - Jagadeesan | B5: =SUMIFS(Debit!$G:$G,Debit!$B:$B,Lists!$A$2,Debit!$E:$E,Lists!$B$2,Debit!$C:$C,Lists!$E$2) -> 62160 | C5: =SUMIFS(Debit!$G:$G,Debit!$B:$B,Lists!$A$2,Debit!$E:$E,Lists!$B$2,Debit!$C:$C,Lists!$E$3) -> 44197 | D5: =SUMIFS(Debit!$G:$G,Debit!$B:$B,Lists!$A$2,Debit!$E:$E,$A5,Debit!$C:$C,Lists!$E$4) -> 0 | E5: =SUMIFS(Credit!$F:$F,Credit!$B:$B,Lists!$A$2,Credit!$D:$D,$A5) -> 0 | F5: =B5+C5+D5-E5 -> 106357
A6: =Lists!$B$3 -> Shareholder - Jagadeshwaran | B6: =SUMIFS(Debit!$G:$G,Debit!$B:$B,Lists!$A$2,Debit!$E:$E,Lists!$B$3,Debit!$C:$C,Lists!$E$2) -> 0 | C6: =SUMIFS(Debit!$G:$G,Debit!$B:$B,Lists!$A$2,Debit!$E:$E,Lists!$B$3,Debit!$C:$C,Lists!$E$3) -> 0 | D6: =SUMIFS(Debit!$G:$G,Debit!$B:$B,Lists!$A$2,Debit!$E:$E,$A6,Debit!$C:$C,Lists!$E$4) -> 0 | E6: =SUMIFS(Credit!$F:$F,Credit!$B:$B,Lists!$A$2,Credit!$D:$D,$A6) -> 0 | F6: =B6+C6+D6-E6 -> 0
A7: =Lists!$B$4 -> Shareholder - Vellingiri | B7: =SUMIFS(Debit!$G:$G,Debit!$B:$B,Lists!$A$2,Debit!$E:$E,Lists!$B$4,Debit!$C:$C,Lists!$E$2) -> 0 | C7: =SUMIFS(Debit!$G:$G,Debit!$B:$B,Lists!$A$2,Debit!$E:$E,Lists!$B$4,Debit!$C:$C,Lists!$E$3) -> 0 | D7: =SUMIFS(Debit!$G:$G,Debit!$B:$B,Lists!$A$2,Debit!$E:$E,$A7,Debit!$C:$C,Lists!$E$4) -> 0 | E7: =SUMIFS(Credit!$F:$F,Credit!$B:$B,Lists!$A$2,Credit!$D:$D,$A7) -> 0 | F7: =B7+C7+D7-E7 -> 0
A8: =Lists!$B$5 -> Vikas | B8: =SUMIFS(Debit!$G:$G,Debit!$B:$B,Lists!$A$2,Debit!$E:$E,Lists!$B$5,Debit!$C:$C,Lists!$E$2) -> 192350 | C8: =SUMIFS(Debit!$G:$G,Debit!$B:$B,Lists!$A$2,Debit!$E:$E,Lists!$B$5,Debit!$C:$C,Lists!$E$3) -> 0 | D8: =SUMIFS(Debit!$G:$G,Debit!$B:$B,Lists!$A$2,Debit!$E:$E,$A8,Debit!$C:$C,Lists!$E$4) -> 0 | E8: =SUMIFS(Credit!$F:$F,Credit!$B:$B,Lists!$A$2,Credit!$D:$D,$A8) -> 0 | F8: =B8+C8+D8-E8 -> 192350
A9: =Lists!$B$6 -> Payable to Alam | B9: =SUMIFS(Debit!$G:$G,Debit!$B:$B,Lists!$A$2,Debit!$E:$E,Lists!$B$6,Debit!$C:$C,Lists!$E$2) -> 182635 | C9: =SUMIFS(Debit!$G:$G,Debit!$B:$B,Lists!$A$2,Debit!$E:$E,Lists!$B$6,Debit!$C:$C,Lists!$E$3) -> 40000 | D9: =SUMIFS(Debit!$G:$G,Debit!$B:$B,Lists!$A$2,Debit!$E:$E,$A9,Debit!$C:$C,Lists!$E$4) -> 0 | E9: =SUMIFS(Credit!$F:$F,Credit!$B:$B,Lists!$A$2,Credit!$D:$D,$A9) -> 400000 | F9: =B9+C9+D9-E9 -> -177365
A10: =Lists!$B$7 -> Union Bank - CC | B10: =SUMIFS(Debit!$G:$G,Debit!$B:$B,Lists!$A$2,Debit!$E:$E,Lists!$B$7,Debit!$C:$C,Lists!$E$2) -> 477215.5 | C10: =SUMIFS(Debit!$G:$G,Debit!$B:$B,Lists!$A$2,Debit!$E:$E,Lists!$B$7,Debit!$C:$C,Lists!$E$3) -> 722512.83 | D10: =SUMIFS(Debit!$G:$G,Debit!$B:$B,Lists!$A$2,Debit!$E:$E,$A10,Debit!$C:$C,Lists!$E$4) -> 0 | E10: =SUMIFS(Credit!$F:$F,Credit!$B:$B,Lists!$A$2,Credit!$D:$D,$A10) -> 0 | F10: =B10+C10+D10-E10 -> 1199728.3
A11: =Lists!$B$8 -> Union Bank - Current | B11: =SUMIFS(Debit!$G:$G,Debit!$B:$B,Lists!$A$2,Debit!$E:$E,Lists!$B$8,Debit!$C:$C,Lists!$E$2) -> 26087 | C11: =SUMIFS(Debit!$G:$G,Debit!$B:$B,Lists!$A$2,Debit!$E:$E,Lists!$B$8,Debit!$C:$C,Lists!$E$3) -> 93696.11 | D11: =SUMIFS(Debit!$G:$G,Debit!$B:$B,Lists!$A$2,Debit!$E:$E,$A11,Debit!$C:$C,Lists!$E$4) -> 0 | E11: =SUMIFS(Credit!$F:$F,Credit!$B:$B,Lists!$A$2,Credit!$D:$D,$A11) -> 0 | F11: =B11+C11+D11-E11 -> 119783.11
A12: =Lists!$B$9 -> Union Bank - Term Loan | B12: =SUMIFS(Debit!$G:$G,Debit!$B:$B,Lists!$A$2,Debit!$E:$E,Lists!$B$9,Debit!$C:$C,Lists!$E$2) -> 1327433.5 | C12: =SUMIFS(Debit!$G:$G,Debit!$B:$B,Lists!$A$2,Debit!$E:$E,Lists!$B$9,Debit!$C:$C,Lists!$E$3) -> 0 | D12: =SUMIFS(Debit!$G:$G,Debit!$B:$B,Lists!$A$2,Debit!$E:$E,$A12,Debit!$C:$C,Lists!$E$4) -> 0 | E12: =SUMIFS(Credit!$F:$F,Credit!$B:$B,Lists!$A$2,Credit!$D:$D,$A12) -> 0 | F12: =B12+C12+D12-E12 -> 1327433.5
A13: Total | B13: =SUM(B5:B12) -> 2267881 | C13: =SUM(C5:C12) -> 900405.94 | D13: =SUM(D5:D12) -> 0 | E13: =SUM(E5:E12) -> 400000 | F13: =B13+C13+D13-E13 -> 2768286.9
A15: =Lists!$A$3 -> Chips Unit
A16: Paid Through | B16: Expenses | C16: Raw Materials | D16: Other Debits | E16: Credit | F16: Total
A17: =Lists!$B$2 -> Shareholder - Jagadeesan | B17: =SUMIFS(Debit!$G:$G,Debit!$B:$B,Lists!$A$3,Debit!$E:$E,Lists!$B$2,Debit!$C:$C,Lists!$E$2) -> 133334.84 | C17: =SUMIFS(Debit!$G:$G,Debit!$B:$B,Lists!$A$3,Debit!$E:$E,Lists!$B$2,Debit!$C:$C,Lists!$E$3) -> 85855 | D17: =SUMIFS(Debit!$G:$G,Debit!$B:$B,Lists!$A$3,Debit!$E:$E,$A17,Debit!$C:$C,Lists!$E$4) -> 0 | E17: =SUMIFS(Credit!$F:$F,Credit!$B:$B,Lists!$A$3,Credit!$D:$D,$A17) -> 0 | F17: =B17+C17+D17-E17 -> 219189.84
A18: =Lists!$B$3 -> Shareholder - Jagadeshwaran | B18: =SUMIFS(Debit!$G:$G,Debit!$B:$B,Lists!$A$3,Debit!$E:$E,Lists!$B$3,Debit!$C:$C,Lists!$E$2) -> 393517 | C18: =SUMIFS(Debit!$G:$G,Debit!$B:$B,Lists!$A$3,Debit!$E:$E,Lists!$B$3,Debit!$C:$C,Lists!$E$3) -> 0 | D18: =SUMIFS(Debit!$G:$G,Debit!$B:$B,Lists!$A$3,Debit!$E:$E,$A18,Debit!$C:$C,Lists!$E$4) -> 0 | E18: =SUMIFS(Credit!$F:$F,Credit!$B:$B,Lists!$A$3,Credit!$D:$D,$A18) -> 0 | F18: =B18+C18+D18-E18 -> 393517
A19: =Lists!$B$4 -> Shareholder - Vellingiri | B19: =SUMIFS(Debit!$G:$G,Debit!$B:$B,Lists!$A$3,Debit!$E:$E,Lists!$B$4,Debit!$C:$C,Lists!$E$2) -> 4186 | C19: =SUMIFS(Debit!$G:$G,Debit!$B:$B,Lists!$A$3,Debit!$E:$E,Lists!$B$4,Debit!$C:$C,Lists!$E$3) -> 0 | D19: =SUMIFS(Debit!$G:$G,Debit!$B:$B,Lists!$A$3,Debit!$E:$E,$A19,Debit!$C:$C,Lists!$E$4) -> 0 | E19: =SUMIFS(Credit!$F:$F,Credit!$B:$B,Lists!$A$3,Credit!$D:$D,$A19) -> 0 | F19: =B19+C19+D19-E19 -> 4186
A20: =Lists!$B$6 -> Payable to Alam | B20: =SUMIFS(Debit!$G:$G,Debit!$B:$B,Lists!$A$3,Debit!$E:$E,Lists!$B$6,Debit!$C:$C,Lists!$E$2) -> 1007254.2 | C20: =SUMIFS(Debit!$G:$G,Debit!$B:$B,Lists!$A$3,Debit!$E:$E,Lists!$B$6,Debit!$C:$C,Lists!$E$3) -> 0 | D20: =SUMIFS(Debit!$G:$G,Debit!$B:$B,Lists!$A$3,Debit!$E:$E,$A20,Debit!$C:$C,Lists!$E$4) -> 0 | E20: =SUMIFS(Credit!$F:$F,Credit!$B:$B,Lists!$A$3,Credit!$D:$D,$A20) -> 13012 | F20: =B20+C20+D20-E20 -> 994242.25
A21: =Lists!$B$7 -> Union Bank - CC | B21: =SUMIFS(Debit!$G:$G,Debit!$B:$B,Lists!$A$3,Debit!$E:$E,Lists!$B$7,Debit!$C:$C,Lists!$E$2) -> 197830.6 | C21: =SUMIFS(Debit!$G:$G,Debit!$B:$B,Lists!$A$3,Debit!$E:$E,Lists!$B$7,Debit!$C:$C,Lists!$E$3) -> 787978.99 | D21: =SUMIFS(Debit!$G:$G,Debit!$B:$B,Lists!$A$3,Debit!$E:$E,$A21,Debit!$C:$C,Lists!$E$4) -> 678303 | E21: =SUMIFS(Credit!$F:$F,Credit!$B:$B,Lists!$A$3,Credit!$D:$D,$A21) -> 0 | F21: =B21+C21+D21-E21 -> 1664112.6
A22: =Lists!$B$8 -> Union Bank - Current | B22: =SUMIFS(Debit!$G:$G,Debit!$B:$B,Lists!$A$3,Debit!$E:$E,Lists!$B$8,Debit!$C:$C,Lists!$E$2) -> 8434.61 | C22: =SUMIFS(Debit!$G:$G,Debit!$B:$B,Lists!$A$3,Debit!$E:$E,Lists!$B$8,Debit!$C:$C,Lists!$E$3) -> 69750.02 | D22: =SUMIFS(Debit!$G:$G,Debit!$B:$B,Lists!$A$3,Debit!$E:$E,$A22,Debit!$C:$C,Lists!$E$4) -> 174000 | E22: =SUMIFS(Credit!$F:$F,Credit!$B:$B,Lists!$A$3,Credit!$D:$D,$A22) -> 600730 | F22: =B22+C22+D22-E22 -> -348545.37
A23: =Lists!$B$9 -> Union Bank - Term Loan | B23: =SUMIFS(Debit!$G:$G,Debit!$B:$B,Lists!$A$3,Debit!$E:$E,Lists!$B$9,Debit!$C:$C,Lists!$E$2) -> 178303 | C23: =SUMIFS(Debit!$G:$G,Debit!$B:$B,Lists!$A$3,Debit!$E:$E,$A23,Debit!$C:$C,Lists!$E$3) -> 0 | D23: =SUMIFS(Debit!$G:$G,Debit!$B:$B,Lists!$A$3,Debit!$E:$E,$A23,Debit!$C:$C,Lists!$E$4) -> 0 | E23: =SUMIFS(Credit!$F:$F,Credit!$B:$B,Lists!$A$3,Credit!$D:$D,$A23) -> 352303 | F23: =B23+C23+D23-E23 -> -174000
A24: Total | B24: =SUM(B17:B23) -> 1922860.3 | C24: =SUM(C17:C23) -> 943584.01 | D24: =SUM(D17:D23) -> 852303 | E24: =SUM(E17:E23) -> 966045 | F24: =B24+C24+D24-E24 -> 2752702.3
A26: =Lists!$A$4 -> Washing Unit
A27: Paid Through | B27: Expenses | C27: Raw Materials | D27: Other Debits | E27: Credit | F27: Total
A28: =Lists!$B$2 -> Shareholder - Jagadeesan | B28: =SUMIFS(Debit!$G:$G,Debit!$B:$B,Lists!$A$4,Debit!$E:$E,Lists!$B$2,Debit!$C:$C,Lists!$E$2) -> 89824 | C28: =SUMIFS(Debit!$G:$G,Debit!$B:$B,Lists!$A$4,Debit!$E:$E,Lists!$B$2,Debit!$C:$C,Lists!$E$3) -> 0 | D28: =SUMIFS(Debit!$G:$G,Debit!$B:$B,Lists!$A$4,Debit!$E:$E,$A28,Debit!$C:$C,Lists!$E$4) -> 0 | E28: =SUMIFS(Credit!$F:$F,Credit!$B:$B,Lists!$A$4,Credit!$D:$D,$A28) -> 0 | F28: =B28+C28+D28-E28 -> 89824
A29: =Lists!$B$3 -> Shareholder - Jagadeshwaran | B29: =SUMIFS(Debit!$G:$G,Debit!$B:$B,Lists!$A$4,Debit!$E:$E,Lists!$B$3,Debit!$C:$C,Lists!$E$2) -> 500 | C29: =SUMIFS(Debit!$G:$G,Debit!$B:$B,Lists!$A$4,Debit!$E:$E,Lists!$B$3,Debit!$C:$C,Lists!$E$3) -> 0 | D29: =SUMIFS(Debit!$G:$G,Debit!$B:$B,Lists!$A$4,Debit!$E:$E,$A29,Debit!$C:$C,Lists!$E$4) -> 0 | E29: =SUMIFS(Credit!$F:$F,Credit!$B:$B,Lists!$A$4,Credit!$D:$D,$A29) -> 0 | F29: =B29+C29+D29-E29 -> 500
A30: =Lists!$B$4 -> Shareholder - Vellingiri | B30: =SUMIFS(Debit!$G:$G,Debit!$B:$B,Lists!$A$4,Debit!$E:$E,Lists!$B$4,Debit!$C:$C,Lists!$E$2) -> 1146155 | C30: =SUMIFS(Debit!$G:$G,Debit!$B:$B,Lists!$A$4,Debit!$E:$E,Lists!$B$4,Debit!$C:$C,Lists!$E$3) -> 0 | D30: =SUMIFS(Debit!$G:$G,Debit!$B:$B,Lists!$A$4,Debit!$E:$E,$A30,Debit!$C:$C,Lists!$E$4) -> 0 | E30: =SUMIFS(Credit!$F:$F,Credit!$B:$B,Lists!$A$4,Credit!$D:$D,$A30) -> 0 | F30: =B30+C30+D30-E30 -> 1146155
A31: =Lists!$B$6 -> Payable to Alam | B31: =SUMIFS(Debit!$G:$G,Debit!$B:$B,Lists!$A$4,Debit!$E:$E,Lists!$B$6,Debit!$C:$C,Lists!$E$2) -> 258669 | C31: =SUMIFS(Debit!$G:$G,Debit!$B:$B,Lists!$A$4,Debit!$E:$E,Lists!$B$6,Debit!$C:$C,Lists!$E$3) -> 0 | D31: =SUMIFS(Debit!$G:$G,Debit!$B:$B,Lists!$A$4,Debit!$E:$E,$A31,Debit!$C:$C,Lists!$E$4) -> 0 | E31: =SUMIFS(Credit!$F:$F,Credit!$B:$B,Lists!$A$4,Credit!$D:$D,$A31) -> 0 | F31: =B31+C31+D31-E31 -> 258669
A32: =Lists!$B$7 -> Union Bank - CC | B32: =SUMIFS(Debit!$G:$G,Debit!$B:$B,Lists!$A$4,Debit!$E:$E,Lists!$B$7,Debit!$C:$C,Lists!$E$2) -> 1005869.8 | C32: =SUMIFS(Debit!$G:$G,Debit!$B:$B,Lists!$A$4,Debit!$E:$E,Lists!$B$7,Debit!$C:$C,Lists!$E$3) -> 0 | D32: =SUMIFS(Debit!$G:$G,Debit!$B:$B,Lists!$A$4,Debit!$E:$E,$A32,Debit!$C:$C,Lists!$E$4) -> 0 | E32: =SUMIFS(Credit!$F:$F,Credit!$B:$B,Lists!$A$4,Credit!$D:$D,$A32) -> 0 | F32: =B32+C32+D32-E32 -> 1005869.8
A33: =Lists!$B$8 -> Union Bank - Current | B33: =SUMIFS(Debit!$G:$G,Debit!$B:$B,Lists!$A$4,Debit!$E:$E,Lists!$B$8,Debit!$C:$C,Lists!$E$2) -> 0 | C33: =SUMIFS(Debit!$G:$G,Debit!$B:$B,Lists!$A$4,Debit!$E:$E,Lists!$B$8,Debit!$C:$C,Lists!$E$3) -> 0 | D33: =SUMIFS(Debit!$G:$G,Debit!$B:$B,Lists!$A$4,Debit!$E:$E,$A33,Debit!$C:$C,Lists!$E$4) -> 0 | E33: =SUMIFS(Credit!$F:$F,Credit!$B:$B,Lists!$A$4,Credit!$D:$D,$A33) -> 0 | F33: =B33+C33+D33-E33 -> 0
A34: =Lists!$B$9 -> Union Bank - Term Loan | B34: =SUMIFS(Debit!$G:$G,Debit!$B:$B,Lists!$A$4,Debit!$E:$E,Lists!$B$9,Debit!$C:$C,Lists!$E$2) -> 0 | C34: =SUMIFS(Debit!$G:$G,Debit!$B:$B,Lists!$A$4,Debit!$E:$E,$A34,Debit!$C:$C,Lists!$E$3) -> 0 | D34: =SUMIFS(Debit!$G:$G,Debit!$B:$B,Lists!$A$4,Debit!$E:$E,$A34,Debit!$C:$C,Lists!$E$4) -> 0 | E34: =SUMIFS(Credit!$F:$F,Credit!$B:$B,Lists!$A$4,Credit!$D:$D,$A34) -> 0 | F34: =B34+C34+D34-E34 -> 0
A35: Total | B35: =SUM(B28:B34) -> 2501017.8 | C35: =SUM(C28:C34) -> 0 | D35: =SUM(D28:D34) -> 0 | E35: =SUM(E28:E34) -> 0 | F35: =B35+C35+D35-E35 -> 2501017.8
A37: Overall Summary
A38: Paid Through | B38: Expenses | C38: Raw Materials | D38: Other Debits | E38: Credit | F38: Total
A39: =Lists!$B$2 -> Shareholder - Jagadeesan | B39: =sum(B5,B17,B28) -> 285318.84 | C39: =sum(C5,C17,C28) -> 130052 | D39: =SUM(D5,D17,D28) -> 0 | E39: =SUM(E5,E17,E28) -> 0 | F39: =B39+C39+D39-E39 -> 415370.84
A40: =Lists!$B$3 -> Shareholder - Jagadeshwaran | B40: =sum(B6,B18,B29) -> 394017 | C40: =sum(C6,C18,C29) -> 0 | D40: =SUM(D6,D18,D29) -> 0 | E40: =SUM(E6,E18,E29) -> 0 | F40: =B40+C40+D40-E40 -> 394017
A41: =Lists!$B$4 -> Shareholder - Vellingiri | B41: =sum(B7,B19,B30) -> 1150341 | C41: =sum(C7,C19,C30) -> 0 | D41: =SUM(D7,D19,D30) -> 0 | E41: =SUM(E7,E19,E30) -> 0 | F41: =B41+C41+D41-E41 -> 1150341
A42: =Lists!$B$5 -> Vikas | B42: =B8 -> 192350 | C42: =C8 -> 0 | D42: =D8 -> 0 | E42: =E8 -> 0 | F42: =B42+C42+D42-E42 -> 192350
A43: =Lists!$B$6 -> Payable to Alam | B43: =sum(B9,B20,B31) -> 1448558.2 | C43: =sum(C9,C20,C31) -> 40000 | D43: =SUM(D9,D20,D31) -> 0 | E43: =SUM(E9,E20,E31) -> 413012 | F43: =B43+C43+D43-E43 -> 1075546.2
A44: =Lists!$B$7 -> Union Bank - CC | B44: =sum(B10,B21,B32) -> 1680915.9 | C44: =sum(C10,C21,C32) -> 1510491.8 | D44: =SUM(D10,D21,D32) -> 678303 | E44: =SUM(E10,E21,E32) -> 0 | F44: =B44+C44+D44-E44 -> 3869710.7
...

Sheet Settlement
A1: Settlement working — auto-calculated (do not edit).
A3: =Lists!$A$2 -> Fibre Unit
A4: Partner | B4: Share % | C4: Paid | D4: Alam share | E4: UBI share | F4: Contribution | G4: Fair share | H4: Net
A5: =Lists!$B$2 -> Shareholder - Jagadeesan | B5: =Lists!$H$3 -> 0.2222 | C5: =SUMIFS(Debit!$G:$G,Debit!$B:$B,Lists!$A$2,Debit!$E:$E,Lists!$B$2) -> 106357 | D5: =Summary!$F$9/2 -> -88682.5 | E5: =SUMIF(Summary!$A$4:$A$12,"Union Bank*",Summary!$F$4:$F$12)/3 -> 882314.98 | F5: =C5+D5+E5 -> 899989.48 | G5: =B5/SUM($B$5:$B$8)*$F$9 -> 615174.88 | H5: =F5-G5 -> 284814.6
A6: =Lists!$B$3 -> Shareholder - Jagadeshwaran | B6: =Lists!$H$4 -> 0.2222 | C6: =SUMIFS(Debit!$G:$G,Debit!$B:$B,Lists!$A$2,Debit!$E:$E,Lists!$B$3) -> 0 | D6: =Summary!$F$9/2 -> -88682.5 | E6: =SUMIF(Summary!$A$4:$A$12,"Union Bank*",Summary!$F$4:$F$12)/3 -> 882314.98 | F6: =C6+D6+E6 -> 793632.48 | G6: =B6/SUM($B$5:$B$8)*$F$9 -> 615174.88 | H6: =F6-G6 -> 178457.6
A7: =Lists!$B$4 -> Shareholder - Vellingiri | B7: =Lists!$H$5 -> 0.2222 | C7: =SUMIFS(Debit!$G:$G,Debit!$B:$B,Lists!$A$2,Debit!$E:$E,Lists!$B$4) -> 0 | D7: =Lists!$H$12*SUMIFS(Debit!$G:$G,Debit!$B:$B,Lists!$A$2,Debit!$E:$E,Lists!$B$6) -> 0 | E7: =SUMIF(Summary!$A$4:$A$12,"Union Bank*",Summary!$F$4:$F$12)/3 -> 882314.98 | F7: =C7+D7+E7 -> 882314.98 | G7: =B7/SUM($B$5:$B$8)*$F$9 -> 615174.88 | H7: =F7-G7 -> 267140.1
A8: =Lists!$B$5 -> Vikas | B8: =Lists!$H$6 -> 0.3333 | C8: =SUMIFS(Debit!$G:$G,Debit!$B:$B,Lists!$A$2,Debit!$E:$E,Lists!$B$5) -> 192350 | D8: =Lists!$H$13*SUMIFS(Debit!$G:$G,Debit!$B:$B,Lists!$A$2,Debit!$E:$E,Lists!$B$6) -> 0 | E8: 0 | F8: =C8+D8+E8 -> 192350 | G8: =B8/SUM($B$5:$B$8)*$F$9 -> 922762.31 | H8: =F8-G8 -> -730412.31
A9: Total (partners + Alam) | C9: =SUM(C5:C8)+SUMIFS(Debit!$G:$G,Debit!$B:$B,Lists!$A$2,Debit!$E:$E,Lists!$B$6) -> 521342 | D9: =SUM(D5:D8)-SUMIFS(Debit!$G:$G,Debit!$B:$B,Lists!$A$2,Debit!$E:$E,Lists!$B$6) -> -400000 | E9: =SUM(E5:E8) -> 2646944.9 | F9: =SUM(F5:F8) -> 2768286.9 | G9: =SUM(G5:G8) -> 2768286.9 | H9: =SUM(H5:H8) -> -2.3283064e-10
A11: =Lists!$A$3 -> Chips Unit
A12: Partner | B12: Share % | C12: Paid | D12: Alam share | E12: UBI share | F12: Contribution | G12: Fair share | H12: Net
A13: =Lists!$B$2 -> Shareholder - Jagadeesan | B13: =Lists!$I$3 -> 0.3333 | C13: =SUMIFS(Debit!$G:$G,Debit!$B:$B,Lists!$A$3,Debit!$E:$E,Lists!$B$2) -> 219189.84 | D13: =VLOOKUP("Payable to Alam",Summary!$A$14:$F$25,6,FALSE)/2 -> 497121.12 | E13: =SUMIF(Summary!$A$17:$A$23,"Union Bank*",Summary!$F$17:$F$23)/3 -> 380522.41 | F13: =C13+D13+E13 -> 1096833.4 | G13: =B13/SUM($B$13:$B$15)*$F$16 -> 917567.44 | H13: =F13-G13 -> 179265.93
A14: =Lists!$B$3 -> Shareholder - Jagadeshwaran | B14: =Lists!$I$4 -> 0.3333 | C14: =SUMIFS(Debit!$G:$G,Debit!$B:$B,Lists!$A$3,Debit!$E:$E,Lists!$B$3) -> 393517 | D14: =VLOOKUP("Payable to Alam",Summary!$A$14:$F$25,6,FALSE)/2 -> 497121.12 | E14: =SUMIF(Summary!$A$17:$A$23,"Union Bank*",Summary!$F$17:$F$23)/3 -> 380522.41 | F14: =C14+D14+E14 -> 1271160.5 | G14: =B14/SUM($B$13:$B$15)*$F$16 -> 917567.44 | H14: =F14-G14 -> 353593.09
A15: =Lists!$B$4 -> Shareholder - Vellingiri | B15: =Lists!$I$5 -> 0.3333 | C15: =SUMIFS(Debit!$G:$G,Debit!$B:$B,Lists!$A$3,Debit!$E:$E,Lists!$B$4) -> 4186 | D15: =Lists!$H$12*SUMIFS(Debit!$G:$G,Debit!$B:$B,Lists!$A$3,Debit!$E:$E,Lists!$B$6) -> 0 | E15: =SUMIF(Summary!$A$17:$A$23,"Union Bank*",Summary!$F$17:$F$23)/3 -> 380522.41 | F15: =C15+D15+E15 -> 384708.41 | G15: =B15/SUM($B$13:$B$15)*$F$16 -> 917567.44 | H15: =F15-G15 -> -532859.03
A16: Total (partners + Alam) | C16: =SUM(C13:C15)+SUMIFS(Debit!$G:$G,Debit!$B:$B,Lists!$A$3,Debit!$E:$E,Lists!$B$6) -> 1624147.1 | D16: =SUM(D13:D15)-SUMIFS(Debit!$G:$G,Debit!$B:$B,Lists!$A$3,Debit!$E:$E,Lists!$B$6) -> -13012 | E16: =SUM(E13:E15) -> 1141567.2 | F16: =SUM(F13:F15) -> 2752702.3 | G16: =SUM(G13:G15) -> 2752702.3 | H16: =SUM(H13:H15) -> -2.3283064e-10
A18: =Lists!$A$4 -> Washing Unit
A19: Partner | B19: Share % | C19: Paid | D19: Alam share | E19: UBI share | F19: Contribution | G19: Fair share | H19: Net
A20: =Lists!$B$2 -> Shareholder - Jagadeesan | B20: =Lists!$J$3 -> 0.3333 | C20: =SUMIFS(Debit!$G:$G,Debit!$B:$B,Lists!$A$4,Debit!$E:$E,Lists!$B$2) -> 89824 | D20: =VLOOKUP("Payable to Alam",Summary!$A$26:$F$37,6,FALSE)/2 -> 129334.5 | E20: =SUMIF(Summary!$A$28:$A$34,"Union Bank*",Summary!$F$28:$F$34)/3 -> 335289.93 | F20: =C20+D20+E20 -> 554448.43 | G20: =B20/SUM($B$20:$B$22)*$F$23 -> 833672.59 | H20: =F20-G20 -> -279224.17
A21: =Lists!$B$3 -> Shareholder - Jagadeshwaran | B21: =Lists!$J$4 -> 0.3333 | C21: =SUMIFS(Debit!$G:$G,Debit!$B:$B,Lists!$A$4,Debit!$E:$E,Lists!$B$3) -> 500 | D21: =VLOOKUP("Payable to Alam",Summary!$A$26:$F$37,6,FALSE)/2 -> 129334.5 | E21: =SUMIF(Summary!$A$28:$A$34,"Union Bank*",Summary!$F$28:$F$34)/3 -> 335289.93 | F21: =C21+D21+E21 -> 465124.43 | G21: =B21/SUM($B$20:$B$22)*$F$23 -> 833672.59 | H21: =F21-G21 -> -368548.17
A22: =Lists!$B$4 -> Shareholder - Vellingiri | B22: =Lists!$J$5 -> 0.3333 | C22: =SUMIFS(Debit!$G:$G,Debit!$B:$B,Lists!$A$4,Debit!$E:$E,Lists!$B$4) -> 1146155 | D22: =Lists!$H$12*SUMIFS(Debit!$G:$G,Debit!$B:$B,Lists!$A$4,Debit!$E:$E,Lists!$B$6) -> 0 | E22: =SUMIF(Summary!$A$28:$A$34,"Union Bank*",Summary!$F$28:$F$34)/3 -> 335289.93 | F22: =C22+D22+E22 -> 1481444.9 | G22: =B22/SUM($B$20:$B$22)*$F$23 -> 833672.59 | H22: =F22-G22 -> 647772.33
A23: Total (partners + Alam) | C23: =SUM(C20:C22)+SUMIFS(Debit!$G:$G,Debit!$B:$B,Lists!$A$4,Debit!$E:$E,Lists!$B$6) -> 1495148 | D23: =SUM(D20:D22)-SUMIFS(Debit!$G:$G,Debit!$B:$B,Lists!$A$4,Debit!$E:$E,Lists!$B$6) -> 0 | E23: =SUM(E20:E22) -> 1005869.8 | F23: =SUM(F20:F22) -> 2501017.8 | G23: =SUM(G20:G22) -> 2501017.8 | H23: =SUM(H20:H22) -> -1.1641532e-10
A25: Overall net position (all units)
A26: Partner | B26: Overall net (₹) | C26: Adjustment (₹) | D26: Adjusted Net (₹)
A27: =Lists!$B$2 -> Shareholder - Jagadeesan | B27: =H5+H13+H20 -> 184856.37 | C27: 0 | D27: =B27+C27 -> 184856.37
A28: =Lists!$B$3 -> Shareholder - Jagadeshwaran | B28: =H6+H14+H21 -> 163502.53 | C28: -116980 | D28: =B28+C28 -> 46522.533
A29: =Lists!$B$4 -> Shareholder - Vellingiri | B29: =H7+H15+H22 -> 382053.41 | C29: 116980 | D29: =B29+C29 -> 499033.41
A30: =Lists!$B$5 -> Vikas | B30: =H8 -> -730412.31 | C30: 0 | D30: =B30+C30 -> -730412.31
A32: Positive = contributed more than fair share (to receive). Alam spend counts as Jagadeesan & Jagadeshwaran's contribution per the Lists sheet attribution.
